Workbook

Sheet Calculos internos
A1: MEKVRA - MODELO INTERNO DE COSTEO Y COTIZACIÓN
A3: Cliente | B3: Lácteos Altos de Teusacá | E3: Proyecto | F3: Automatización de línea de producción láctea (3 productos)
A4: Fecha cotización | B4: 46305 | C4: Vigencia (días) | D4: 30 | E4: IVA ventas (%) | F4: 0.19 | G4: Contingencia proyecto (%) | H4: 0.05
A6: 1. COSTO LABORAL Y HORA PRODUCTIVA
A7: Rol | B7: Salario base mensual | C7: Factor cargas empresa | D7: Horas productivas/mes | E7: Personas | F7: Costo empresa mensual | G7: Costo hora cargado
A8: Líder de automatización | B8: 5300000 | C8: 0.38 | D8: 150 | E8: 1 | F8: =B8*(1+C8)*E8 -> 7314000 | G8: =F8/D8 -> 48760
A9: Líder de ingeniería | B9: 5600000 | C9: 0.38 | D9: 150 | E9: 1 | F9: =B9*(1+C9)*E9 -> 7728000 | G9: =F9/D9 -> 51520
A10: Líder de gestión y administración | B10: 5000000 | C10: 0.38 | D10: 150 | E10: 1 | F10: =B10*(1+C10)*E10 -> 6900000 | G10: =F10/D10 -> 46000
A11: Gerencia, desarrollo y finanzas | B11: 6300000 | C11: 0.38 | D11: 150 | E11: 1 | F11: =B11*(1+C11)*E11 -> 8694000 | G11: =F11/D11 -> 57960
A12: Líder de instrumentación y software | B12: 5500000 | C12: 0.38 | D12: 150 | E12: 1 | F12: =B12*(1+C12)*E12 -> 7590000 | G12: =F12/D12 -> 50600
A13: Área Legal | B13: 2000000 | E13: 1 | G13: =E13*B13 -> 2000000
A14: Personal profesional especialista | B14: 4500000 | E14: 2 | G14: =B14*E14 -> 9000000
A15: Personal Tecnico (instalacion) | B15: 2300000 | C15: 0.38 | D15: 155 | E15: 4 | F15: =B15*(1+C15)*E15 -> 12696000 | G15: =F15/D15 -> 81909.677
A17: 2. COSTEO DE SERVICIOS, EQUIPOS Y OTROS ÍTEMS
A18: Etapa / ítem | B18: Tipo | C18: Líder de automatización | D18: Líder de ingeniería | E18: Líder de gestión y administración | F18: Gerencia, desarrollo y finanzas | G18: Líder de instrumentación y software | H18: Personal Tecnico (instalacion) | I18: Horas estimadas | J18: Costo hora / unidad | K18: Costo personal | L18: Visitas por Fase a la empresa | M18: Personas involucradas | N18: Costo de transporte | O18: Costos externos/otros | P18: Costo directo total | Q18: Margen objetivo | R18: Precio antes IVA | S18: Notas / supuesto
A19: Diagnóstico y levantamiento | B19: Servicio | C19: 140 | D19: 200 | E19: 140 | F19: 100 | G19: 140 | H19: 0 | I19: =SUM(C19:H19) -> 720 | J19: =$G$8 -> 48760 | K19: =I19*J19 -> 35107200 | L19: 4 | M19: 6 | N19: 200000 | O19: =(G14+(N19*M19*L19))*1.15 -> 15870000 | P19: =K19+O19 -> 50977200 | Q19: 0.34 | R19: =P19/(1-Q19) -> 77238182 | S19: Consultoría y levantamiento
A20: Ingeniería conceptual/detalle | B20: Servicio | C20: 165 | D20: 225 | E20: 100 | F20: 80 | G20: 135 | H20: 0 | I20: =SUM(C20:H20) -> 705 | J20: =$G$9 -> 51520 | K20: =I20*J20 -> 36321600 | L20: 2 | M20: 3 | N20: 200000 | O20: =N20*M20*L20*1.15 -> 1380000 | P20: =K20+O20 -> 37701600 | Q20: 0.35 | R20: =P20/(1-Q20) -> 58002462 | S20: Diseño y documentación
A21: Programación PLC/HMI/SCADA | B21: Servicio | C21: 55 | D21: 20 | E21: 0 | F21: 0 | G21: 45 | H21: 0 | I21: =SUM(C21:H21) -> 120 | J21: =$G$10 -> 46000 | K21: =I21*J21 -> 5520000 | L21: 0 | M21: 0 | N21: 200000 | O21: =N21*M21*L21*1.15 -> 0 | P21: =K21+O21 -> 5520000 | Q21: 0.35 | R21: =P21/(1-Q21) -> 8492307.7 | S21: Desarrollo e integración
A22: Gestión y coordinación proyecto | B22: Servicio | C22: 50 | D22: 55 | E22: 150 | F22: 150 | G22: 40 | H22: 0 | I22: =SUM(C22:H22) -> 445 | J22: =$G$11 -> 57960 | K22: =I22*J22 -> 25792200 | L22: 6 | M22: 5 | N22: 200000 | O22: =(N22*M22*L22*1.15)+G13 -> 8900000 | P22: =K22+O22 -> 34692200 | Q22: 0.3 | R22: =P22/(1-Q22) -> 49560286 | S22: Planeación y seguimiento
A23: Instalación y puesta en marcha | B23: Servicio | C23: 42 | D23: 40 | E23: 10 | F23: 10 | G23: 25 | H23: =30*E15 -> 120 | I23: =SUM(C23:H23) -> 247 | J23: =$G$12+$G$15 -> 132509.68 | K23: =I23*J23 -> 32729890 | L23: 60 | M23: 10 | N23: 200000 | O23: =N23*M23*L23*1.15 -> 138000000 | P23: =K23+O23 -> 1.7072989e+08 | Q23: 0.32 | R23: =P23/(1-Q23) -> 2.5107337e+08 | S23: Instalación, pruebas y capacitación
A24: Soporte/posventa (opcional) | B24: Servicio | C24: 15 | D24: 15 | E24: 10 | F24: 10 | G24: 15 | H24: 10 | I24: =SUM(C24:H24) -> 75 | J24: =$G$8 -> 48760 | K24: =I24*J24 -> 3657000 | L24: 2 | M24: 3 | N24: 200000 | O24: =N24*M24*L24*1.15 -> 1380000 | P24: =K24+O24 -> 5037000 | Q24: 0.33 | R24: =P24/(1-Q24) -> 7517910.4 | S24: Horas estimadas de soporte
A26: 3. COSTEO DE LICENCIAS DE SOFTWARE
A27: Sofware/ Licencia | B27: Uso | C27: Tipo de licencia | D27: Costo licencia en su moneda | E27: Tasa de cambio | F27: Costo licencia en COP | G27: IVA u otros impuestos (%) | H27: Duracion de la licencia (meses) | I27: Duracion del proyecto (meses) | J27: Costo estimado antes de IVA
A28: Tecnomatix Plant Simulation (standar) | B28: Simulación flujo/producción | D28: 1049 | E28: 3211 | F28: =E28*D28 -> 3368339 | G28: 0.19 | H28: 1 | I28: 4 | J28: =F28*(I28/H28) -> 13473356
A29: Factory I/O | B29: Simulación y pruebas PLC | C29: individual | D29: 278 | E29: 3602 | F29: =E29*D29 -> 1001356 | G29: 0.19 | H29: 12 | I29: 10 | J29: =F29*(I29/H29) -> 834463.33
A30: Node-RED | B30: Integración IoT | D30: 0 | E30: 0 | F30: =E30*D30 -> 0 | G30: 0.19 | H30: 1 | I30: 4 | J30: =F30*(I30/H30) -> 0
A31: Autocad | B31: Diseño electrico | C31: individual | D31: 260 | E31: 3211 | F31: =E31*D31 -> 834860 | G31: 0.19 | H31: 1 | I31: 2 | J31: =F31*(I31/H31) -> 1669720
A32: Studio 5000/RS-link | B32: Programación de PLC Allen-Bradley/Rockwell | D32: 840 | E32: 3211 | F32: =E32*D32 -> 2697240 | G32: 0.19 | H32: 1 | I32: 10 | J32: =F32*(I32/H32) -> 26972400
A33: Draw.IO | B33: Diseño de diagramas de procesos, P&ID, etc. | D33: 0 | E33: 3211 | F33: =E33*D33 -> 0 | G33: 0.19 | H33: 1 | J33: =F33*(I33/H33) -> 0
A34: Microsoft 365 | B34: comunicacion y documentación | D34: 37.78 | E34: 3602 | F34: =E34*D34 -> 136083.56 | G34: 0.19 | H34: 12 | I34: 12 | J34: =F34*(I34/H34) -> 136083.56
F35: =E35*D35 -> 0 | H35: 1 | J35: =F35*(I35/H35) -> 0
F36: =E36*D36 -> 0 | H36: 1 | J36: =F36*(I36/H36) -> 0
F37: =E37*D37 -> 0 | H37: 1 | J37: =F37*(I37/H37) -> 0
A39: 4. COSTEO DE EQUIPOS IMPORTADOS (POR ÍTEM)
A40: Equipo / referencia | B40: Proveedor / origen | C40: Precio proveedor COP | D40: Flete internacional + seguro hasta importación | E40: Honorario de agencia de aduana [%] | F40: Honorario de agencia de aduana [COP] | G40: Valor en aduana (base provisional) | H40: Arancel (%) | I40: Arancel COP | J40: Gastos aduaneros/locales + transporte nacional | K40: Costo antes IVA recuperable | L40: Margen objetivo | M40: IVA importación (%) | N40: IVA importación estimado | O40: Precio equipo antes IVA
A41: GASTI R-Line L | B41: Leominster - Massachusetts | C41: 2430000000 | D41: =1400*E31+C41*0.01 -> 28795400 | E41: 0.01 | F41: =(C41+D41)*E41 -> 24587954 | G41: =C41+D41+F41 -> 2483383354 | H41: 0 | I41: =G41*H41 -> 0 | J41: 25000000 | K41: =G41+I41+J41 -> 2508383354 | L41: 0.2 | M41: 0.19 | N41: =(G41+I41)*M41 -> 4.7184284e+08 | O41: =K41/(1-L41) -> 3135479193
A42: Equipo 2 | B42: Por definir | C42: 0 | D42: 0 | G42: =C42+D42 -> 0 | H42: 0 | I42: =G42*H42 -> 0 | J42: 0 | K42: =G42+I42+J42 -> 0 | L42: 0.2 | M42: 0.19 | N42: =(G42+I42)*M42 -> 0 | O42: =K42/(1-L42) -> 0
A43: Equipo 3 | B43: Por definir | C43: 0 | D43: 0 | G43: =C43+D43 -> 0 | H43: 0 | I43: =G43*H43 -> 0 | J43: 0 | K43: =G43+I43+J43 -> 0 | L43: 0.2 | M43: 0.19 | N43: =(G43+I43)*M43 -> 0 | O43: =K43/(1-L43) -> 0
A44: Equipo 4 | B44: Por definir | C44: 0 | D44: 0 | G44: =C44+D44 -> 0 | H44: 0 | I44: =G44*H44 -> 0 | J44: 0 | K44: =G44+I44+J44 -> 0 | L44: 0.2 | M44: 0.19 | N44: =(G44+I44)*M44 -> 0 | O44: =K44/(1-L44) -> 0
A45: Equipo 5 | B45: Por definir | C45: 0 | D45: 0 | G45: =C45+D45 -> 0 | H45: 0 | I45: =G45*H45 -> 0 | J45: 0 | K45: =G45+I45+J45 -> 0 | L45: 0.2 | M45: 0.19 | N45: =(G45+I45)*M45 -> 0 | O45: =K45/(1-L45) -> 0
...

Sheet Resumen cliente
A1: MEKVRA INGENIERÍA E INTEGRACIÓN S.A.S. | PROPUESTA ECONÓMICA
A3: Cliente | B3: ='Calculos internos'!B3 -> Lácteos Altos de Teusacá | D3: Fecha | E3: ='Calculos internos'!B4 -> 46305
A4: Proyecto | B4: ='Calculos internos'!F3 -> Automatización de línea de producción láctea (3 productos)
A5: Vigencia | B5: ='Calculos internos'!D4&" días" -> 30 días
A7: ALCANCE ECONÓMICO
A8: Ítem | B8: Descripción | C8: Cantidad / unidad | D8: Precio unitario antes IVA | E8: Subtotal antes IVA | F8: Observaciones
A9: 1 | B9: Diagnóstico y levantamiento | C9: 1 | D9: ='Calculos internos'!R19 -> 77238182 | E9: =C9*D9 -> 77238182 | F9: Alcance sujeto a validación en planta
A10: 2 | B10: Ingeniería conceptual/detalle | C10: 1 | D10: ='Calculos internos'!R20+SUM('Calculos internos'!J28:J37) -> 1.0108848e+08 | E10: =C10*D10 -> 1.0108848e+08 | F10: Según alcance aprobado
A11: 3 | B11: Programación PLC/HMI/SCADA | C11: 1 | D11: ='Calculos internos'!R21 -> 8492307.7 | E11: =C11*D11 -> 8492307.7 | F11: Incluye pruebas descritas en propuesta
A12: 4 | B12: Gestión y coordinación | C12: 1 | D12: ='Calculos internos'!R22 -> 49560286 | E12: =C12*D12 -> 49560286 | F12: Según cronograma
A13: 5 | B13: Instalación y puesta en marcha | C13: 1 | D13: ='Calculos internos'!R23 -> 2.5107337e+08 | E13: =C13*D13 -> 2.5107337e+08 | F13: No incluye trabajos no especificados
A14: 6 | B14: Equipos e instrumentación | C14: 1 | D14: =SUM('Calculos internos'!O41:O45) -> 3135479193 | E14: =C14*D14 -> 3135479193 | F14: Estimación
A15: 7 | B15: Soporte posventa opcional | C15: 1 | D15: ='Calculos internos'!R24 -> 7517910.4 | E15: =C15*D15 -> 7517910.4 | F15: garantía según contrato
A16: 8
A17: 9
D19: Subtotal antes de IVA | E19: =SUM(E9:E15) -> 3630449731
D20: Contingencia | E20: ='Calculos internos'!D58 -> 15232895
D21: Nuevo Subtotal antes de IVA | E21: =E20+E19 -> 3645682625
D22: IVA estimado | E22: =E21*'Calculos internos'!F4 -> 6.926797e+08
D23: Total cotización | E23: =E21+E22 -> 4338362324
A25: CONDICIONES COMERCIALES
A27: 1. La cotización es preliminar y está sujeta a la definición del alcance, productos, capacidad y equipos existentes.
A28: 2. Los equipos importados se cotizan con base en subpartida, país de origen, flete, seguro, tributos y disponibilidad confirmados; cambios de tasa de cambio o tarifas pueden modificar el precio.
A29: 3. Forma de pago sugerida: anticipo que cubra compromisos de compra y costos iniciales; pagos restantes contra hitos de ingeniería, suministro, instalación y aceptación. Definir porcentajes en contrato.
A30: 4. El IVA mostrado es una estimación y debe validarse por concepto y estructura contractual antes de emitir factura.
A31: 5. Garantía y posventa se regirán por alcance, duración, exclusiones, tiempos de respuesta y condiciones operativas pactadas.
A32: 6. No incluye actividades, equipos, permisos, obra civil, adecuaciones eléctricas o de proceso que no estén expresamente listados.

Sheet Hoja 1
A1: Marca | B1: Modelo | C1: Lugar de origen | D1: Distribucion en Colombia | E1: aprox precio Comercial | F1: capacidad | G1: N° de llenados
A2: IMA | B2: GASTI R-Line | C2: Leominster - Massachusetts | D2: Axioma B2B Marketing | F2: 21600 vasos/h | G2: 4
A3: GRUNWALD | B3: Rotari 12000 | F3: 18000 | G3: 46177
A4: Primodan | F4: 24000
A6: contenedor | B6: 20' FCL | C6: Importar desde EEUU a Colombia: Guía 2026 - Logintec CO

Sheet Hoja 2
A1: Perfil de mercancia
A2: codigo nomenclatura | B2: Nivel de nomenclatura | C2: Descripcion | D2: Gravamen | E2: iva | F2: gavamen por acuerdos
A3: 8422.30.90.20 | B3: ARIAN | C3: máquinas y aparatos para llenar, cerrar, tapar, taponar o etiquetar botellas, botes o latas, cajas, sacos (bolsas) o demás continentes | D3: 0.05 | E3: 0.19 | F3: 0 | G3: Compilación Jurídica de la DIAN - Decreto 1881 de 2021

Sheet Hoja 3
